<?xml version="1.0" encoding="utf-8"?>

<!-- This URDF was automatically created by SolidWorks to URDF Exporter! Originally created by Stephen Brawner (brawner@gmail.com) 
     Commit Version: 1.6.0-4-g7f85cfe  Build Version: 1.6.7995.38578
     For more information, please see http://wiki.ros.org/sw_urdf_exporter -->
<robot name="BrainCoRevo1R_RightHand"> 
  <link name="base_link"/>  
  <link name="connector_link"> 
    <visual> 
      <origin xyz="0 0 0" rpy="0 0 0"/>  
      <geometry> 
        <mesh filename="visual/glb/connector_link.glb"/> 
      </geometry>  
    </visual>  
    <collision> 
      <origin xyz="0 0 0" rpy="0 0 0"/>  
      <geometry> 
        <mesh filename="collision/rough/connector_link.obj"/> 
      </geometry> 
    </collision> 
  </link>  
  <joint name="CONNECTOR" type="fixed"> 
    <origin xyz="0 0 0" rpy="1.5707963267948966 0 0"/> 
    <parent link="base_link"/>  
    <child link="connector_link"/>  
  </joint> 
  <link name="hand_base_link"> 
    <inertial> 
      <origin xyz="-0.00099373 0.040537 -0.0022835" rpy="0 0 0"/>  
      <mass value="0.427"/>  
      <inertia ixx="3.4364E-05" ixy="-1.2404E-06" ixz="5.654E-07" iyy="3.9467E-05" iyz="3.8955E-06" izz="6.3984E-05"/> 
    </inertial>  
    <visual> 
      <origin xyz="0 0 0" rpy="0 0 0"/>  
      <geometry> 
        <mesh filename="visual/glb/hand_base_link.glb"/> 
      </geometry>  
      <material name=""> 
        <color rgba="0.75 0.75294 0.75294 1"/> 
      </material> 
    </visual>  
    <collision> 
      <origin xyz="0 0 0" rpy="0 0 0"/>  
      <geometry> 
        <mesh filename="collision/rough/hand_base_link.obj"/> 
      </geometry> 
    </collision> 
  </link>  
  <joint name="HAND_BASE" type="fixed"> 
    <origin xyz="0 0 0.002" rpy="0 0 0"/>  
    <parent link="connector_link"/>  
    <child link="hand_base_link"/> 
  </joint>  
  <link name="base_offset"> </link>  
  <joint name="BASE_OFFSET" type="fixed"> 
    <origin xyz="0 0.0298242 0" rpy="0 0 0"/>  
    <parent link="hand_base_link"/>  
    <child link="base_offset"/>
  </joint>

  <link name="t_cmc_yaw_link"> 
    <inertial> 
      <origin xyz="0.0062041 -7.9383E-08 0.0015306" rpy="0 0 0"/>  
      <mass value="0.005"/>  
      <inertia ixx="4.0639E-08" ixy="5.8675E-13" ixz="2.4299E-09" iyy="9.2485E-08" iyz="7.1049E-13" izz="8.5586E-08"/> 
    </inertial>  
    <visual> 
      <origin xyz="0 0 0" rpy="0 0 0"/>  
      <geometry> 
        <mesh filename="visual/glb/t_cmc_yaw_link.glb"/> 
      </geometry>  
      <material name=""> 
        <color rgba="1 1 1 1"/> 
      </material> 
    </visual>  
    <collision> 
      <origin xyz="0 0 0" rpy="0 0 0"/>  
      <geometry> 
        <mesh filename="collision/rough/t_cmc_yaw_link.obj"/> 
      </geometry> 
    </collision> 
  </link>   
  <link name="t_mcp_link"> 
    <inertial> 
      <origin xyz="0.0083564 0.037204 -3.5884E-07" rpy="0 0 0"/>  
      <mass value="0.04"/>  
      <inertia ixx="7.1498E-06" ixy="2.0157E-07" ixz="-6.0726E-11" iyy="9.1501E-07" iyz="5.4502E-10" izz="6.8747E-06"/> 
    </inertial>  
    <visual> 
      <origin xyz="0 0 0" rpy="0 0 0"/>  
      <geometry> 
        <mesh filename="visual/glb/t_mcp_link.glb"/> 
      </geometry>  
      <material name=""> 
        <color rgba="0.75294 0.75294 0.75294 1"/> 
      </material> 
    </visual>  
    <collision> 
      <origin xyz="0 0 0" rpy="0 0 0"/>  
      <geometry> 
        <mesh filename="collision/rough/t_mcp_link.obj"/> 
      </geometry> 
    </collision> 
  </link>  
  <link name="if_mcp_pitch_link"> 
    <inertial> 
      <origin xyz="-5.571E-07 0.016609 0.00045746" rpy="0 0 0"/>  
      <mass value="0.008"/>  
      <inertia ixx="3.3526E-07" ixy="2.9401E-11" ixz="-2.4782E-12" iyy="1.0133E-07" iyz="2.0576E-08" izz="3.7092E-07"/> 
    </inertial>  
    <visual> 
      <origin xyz="0 0 0" rpy="0 0 0"/>  
      <geometry> 
        <mesh filename="visual/glb/if_mcp_pitch_link.glb"/> 
      </geometry>  
      <material name=""> 
        <color rgba="0.75294 0.75294 0.75294 1"/> 
      </material> 
    </visual>  
    <collision> 
      <origin xyz="0 0 0" rpy="0 0 0"/>  
      <geometry> 
        <mesh filename="collision/rough/if_mcp_pitch_link.obj"/> 
      </geometry> 
    </collision> 
  </link>  
  <link name="if_dip_link"> 
    <inertial> 
      <origin xyz="5.9401E-06 0.025449 0.003278" rpy="0 0 0"/>  
      <mass value="0.011"/>  
      <inertia ixx="8.4801E-07" ixy="-1.0878E-09" ixz="-1.3683E-10" iyy="1.4147E-07" iyz="-1.0078E-07" izz="8.5502E-07"/> 
    </inertial>  
    <visual> 
      <origin xyz="0 0 0" rpy="0 0 0"/>  
      <geometry> 
        <mesh filename="visual/glb/if_dip_link.glb"/> 
      </geometry>  
      <material name=""> 
        <color rgba="0.75294 0.75294 0.75294 1"/> 
      </material> 
    </visual>  
    <collision> 
      <origin xyz="0 0 0" rpy="0 0 0"/>  
      <geometry> 
        <mesh filename="collision/rough/if_dip_link.obj"/> 
      </geometry> 
    </collision> 
  </link>  
  <link name="mf_mcp_pitch_link"> 
    <inertial> 
      <origin xyz="2.3779E-07 0.020205 0.00053993" rpy="0 0 0"/>  
      <mass value="0.011"/>  
      <inertia ixx="5.5624E-07" ixy="8E-12" ixz="-8.5151E-12" iyy="1.3298E-07" iyz="2.669E-08" izz="6.0146E-07"/> 
    </inertial>  
    <visual> 
      <origin xyz="0 0 0" rpy="0 0 0"/>  
      <geometry> 
        <mesh filename="visual/glb/mf_mcp_pitch_link.glb"/> 
      </geometry>  
      <material name=""> 
        <color rgba="0.75294 0.75294 0.75294 1"/> 
      </material> 
    </visual>  
    <collision> 
      <origin xyz="0 0 0" rpy="0 0 0"/>  
      <geometry> 
        <mesh filename="collision/rough/mf_mcp_pitch_link.obj"/> 
      </geometry> 
    </collision> 
  </link>  
  <link name="mf_dip_link"> 
    <inertial> 
      <origin xyz="5.9404E-06 0.025449 0.003278" rpy="0 0 0"/>  
      <mass value="0.011"/>  
      <inertia ixx="8.4801E-07" ixy="-1.0879E-09" ixz="-1.3705E-10" iyy="1.4147E-07" iyz="-1.0078E-07" izz="8.5501E-07"/> 
    </inertial>  
    <visual> 
      <origin xyz="0 0 0" rpy="0 0 0"/>  
      <geometry> 
        <mesh filename="visual/glb/mf_dip_link.glb"/> 
      </geometry>  
      <material name=""> 
        <color rgba="0.75294 0.75294 0.75294 1"/> 
      </material> 
    </visual>  
    <collision> 
      <origin xyz="0 0 0" rpy="0 0 0"/>  
      <geometry> 
        <mesh filename="collision/rough/mf_dip_link.obj"/> 
      </geometry> 
    </collision> 
  </link>  
  <link name="rf_mcp_pitch_link"> 
    <inertial> 
      <origin xyz="2.4507E-07 0.020236 0.00042373" rpy="0 0 0"/>  
      <mass value="0.011"/>  
      <inertia ixx="5.5623E-07" ixy="7.4604E-12" ixz="-8.5876E-12" iyy="1.3295E-07" iyz="2.7719E-08" izz="6.0149E-07"/> 
    </inertial>  
    <visual> 
      <origin xyz="0 0 0" rpy="0 0 0"/>  
      <geometry> 
        <mesh filename="visual/glb/rf_mcp_pitch_link.glb"/> 
      </geometry>  
      <material name=""> 
        <color rgba="0.75294 0.75294 0.75294 1"/> 
      </material> 
    </visual>  
    <collision> 
      <origin xyz="0 0 0" rpy="0 0 0"/>  
      <geometry> 
        <mesh filename="collision/rough/rf_mcp_pitch_link.obj"/> 
      </geometry> 
    </collision> 
  </link>  
  <link name="rf_dip_link"> 
    <inertial> 
      <origin xyz="5.5799E-07 0.020388 0.0029077" rpy="0 0 0"/>  
      <mass value="0.008"/>  
      <inertia ixx="3.6793E-07" ixy="-6.504E-13" ixz="-1.1541E-11" iyy="8.4208E-08" iyz="-4.5737E-08" izz="3.8369E-07"/> 
    </inertial>  
    <visual> 
      <origin xyz="0 0 0" rpy="0 0 0"/>  
      <geometry> 
        <mesh filename="visual/glb/rf_dip_link.glb"/> 
      </geometry>  
      <material name=""> 
        <color rgba="0.75294 0.75294 0.75294 1"/> 
      </material> 
    </visual>  
    <collision> 
      <origin xyz="0 0 0" rpy="0 0 0"/>  
      <geometry> 
        <mesh filename="collision/rough/rf_dip_link.obj"/> 
      </geometry> 
    </collision> 
  </link> 
  <link name="lf_mcp_pitch_link"> 
    <inertial> 
      <origin xyz="-5.4618E-07 0.016662 0.00040738" rpy="0 0 0"/>  
      <mass value="0.008"/>  
      <inertia ixx="3.3526E-07" ixy="2.8461E-11" ixz="-2.3358E-12" iyy="1.0129E-07" iyz="2.1346E-08" izz="3.7096E-07"/> 
    </inertial>  
    <visual> 
      <origin xyz="0 0 0" rpy="0 0 0"/>  
      <geometry> 
        <mesh filename="visual/glb/lf_mcp_pitch_link.glb"/> 
      </geometry>  
      <material name=""> 
        <color rgba="0.75294 0.75294 0.75294 1"/> 
      </material> 
    </visual>  
    <collision> 
      <origin xyz="0 0 0" rpy="0 0 0"/>  
      <geometry> 
        <mesh filename="collision/rough/lf_mcp_pitch_link.obj"/> 
      </geometry> 
    </collision> 
  </link> 
  <link name="lf_dip_link"> 
    <inertial> 
      <origin xyz="1.062E-05 0.017869 0.0020864" rpy="0 0 0"/>  
      <mass value="0.008"/>  
      <inertia ixx="2.3262E-07" ixy="-4.9135E-10" ixz="-4.9506E-11" iyy="6.4304E-08" iyz="-2.3564E-08" izz="2.4916E-07"/> 
    </inertial>  
    <visual> 
      <origin xyz="0 0 0" rpy="0 0 0"/>  
      <geometry> 
        <mesh filename="visual/glb/lf_dip_link.glb"/> 
      </geometry>  
      <material name=""> 
        <color rgba="0.75294 0.75294 0.75294 1"/> 
      </material> 
    </visual>  
    <collision> 
      <origin xyz="0 0 0" rpy="0 0 0"/>  
      <geometry> 
        <mesh filename="collision/rough/lf_dip_link.obj"/> 
      </geometry> 
    </collision> 
  </link>  

  <joint name="T_CMC_YAW" type="revolute"> 
    <origin xyz="0.0245 0.0242 0.021628" rpy="0 -0.49642 0"/>  
    <parent link="base_offset"/>  
    <child link="t_cmc_yaw_link"/>  
    <axis xyz="0 -1 0"/>  
    <limit lower="0" upper="1.5708" effort="0" velocity="0"/> 
  </joint> 
  <joint name="T_MCP" type="revolute"> 
    <origin xyz="0.013647 0 0" rpy="-0.39332 0.31115 -0.93514"/>  
    <parent link="t_cmc_yaw_link"/>  
    <child link="t_mcp_link"/>  
    <axis xyz="0 0 1"/>  
    <limit lower="0" upper="0.87266" effort="0" velocity="0"/> 
  </joint>  
  <joint name="IF_MCP_PITCH" type="revolute"> 
    <origin xyz="0.029003 0.088231 -0.0039488" rpy="-0.09929 -0.054667 -0.031168"/>  
    <parent link="base_offset"/>  
    <child link="if_mcp_pitch_link"/>  
    <axis xyz="1 0 0"/>  
    <limit lower="0" upper="1.309" effort="0" velocity="0"/> 
  </joint>  
  <joint name="IF_DIP" type="revolute"> 
    <origin xyz="0 0.035 0" rpy="0.19353 0 0"/>  
    <parent link="if_mcp_pitch_link"/>  
    <child link="if_dip_link"/> 
    <axis xyz="1 0 0"/>  
    <limit lower="0" upper="2.0944" effort="0" velocity="0"/> 
    <mimic joint="IF_MCP_PITCH" multiplier="1.2" offset="0.19373154697137057"/>
  </joint>  
  <joint name="MF_MCP_PITCH" type="revolute"> 
    <origin xyz="0.008 0.091935 -0.0082038" rpy="-0.069813 0 0"/>  
    <parent link="base_offset"/>  
    <child link="mf_mcp_pitch_link"/>  
    <axis xyz="1 0 0"/>  
    <limit lower="0" upper="1.309" effort="0" velocity="0"/> 
  </joint>  
  <joint name="MF_DIP" type="revolute"> 
    <origin xyz="0 0.042 0" rpy="0.18357 0 0"/>  
    <parent link="mf_mcp_pitch_link"/>  
    <child link="mf_dip_link"/>  
    <axis xyz="1 0 0"/>  
    <limit lower="0" upper="2.0944" effort="0" velocity="0"/> 
    <mimic joint="MF_MCP_PITCH" multiplier="1.2" offset="0.1832595714594046"/>
  </joint>  
  <joint name="RF_MCP_PITCH" type="revolute"> 
    <origin xyz="-0.013103 0.089947 -0.0080786" rpy="-0.079113 0.054667 0.031168"/>  
    <parent link="base_offset"/>  
    <child link="rf_mcp_pitch_link"/>  
    <axis xyz="1 0 0"/>  
    <limit lower="0" upper="1.309" effort="0" velocity="0"/> 
  </joint>  
  <joint name="RF_DIP" type="revolute"> 
    <origin xyz="0 0.042 0" rpy="0.16583 0 0"/>  
    <parent link="rf_mcp_pitch_link"/>  
    <child link="rf_dip_link"/>  
    <axis xyz="1 0 0"/>  
    <limit lower="0" upper="2.0944" effort="0" velocity="0"/> 
    <mimic joint="RF_MCP_PITCH" multiplier="1.2" offset="0.16580627893946132"/>
  </joint>  
  <joint name="LF_MCP_PITCH" type="revolute"> 
    <origin xyz="-0.033731 0.083727 -0.0036339" rpy="-0.094666 0.057099 0.065996"/>  
    <parent link="base_offset"/>  
    <child link="lf_mcp_pitch_link"/>  
    <axis xyz="1 0 0"/>  
    <limit lower="0" upper="1.309" effort="0" velocity="0"/> 
  </joint>  
  <joint name="LF_DIP" type="revolute"> 
    <origin xyz="0 0.035 0" rpy="0.20294 0 0"/>  
    <parent link="lf_mcp_pitch_link"/>  
    <child link="lf_dip_link"/>  
    <axis xyz="1 0 0"/>  
    <limit lower="0" upper="2.0944" effort="0" velocity="0"/> 
    <mimic joint="LF_MCP_PITCH" multiplier="1.2" offset="0.20245819323134223"/>
  </joint> 

</robot>
