<?xml version="1.0" encoding="utf-8"?>

<!-- This URDF was automatically created by SolidWorks to URDF Exporter! Originally created by Stephen Brawner (brawner@gmail.com) 
     Commit Version: 1.6.0-4-g7f85cfe  Build Version: 1.6.7995.38578
     For more information, please see http://wiki.ros.org/sw_urdf_exporter -->
<robot name="BrainCoRevo1R_LeftHand"> 
  <link name="base_link"/>  
  <link name="connector_link"> 
    <visual> 
      <origin xyz="0 0 0" rpy="0 0 0"/>  
      <geometry> 
        <mesh filename="visual/glb/connector_link.glb"/> 
      </geometry>  
    </visual>  
    <collision> 
      <origin xyz="0 0 0" rpy="0 0 0"/>  
      <geometry> 
        <mesh filename="collision/rough/connector_link.obj"/> 
      </geometry> 
    </collision> 
  </link>  
  <joint name="CONNECTOR" type="fixed"> 
    <origin xyz="0 0 0" rpy="1.5707963267948966 0 3.141592653589793"/> 
    <parent link="base_link"/>  
    <child link="connector_link"/>  
  </joint> 
  <link name="hand_base_link"> 
    <inertial> 
      <origin xyz="0.0017239 0.0051432 -0.031065" rpy="0 0 0"/>  
      <mass value="0.427"/>  
      <inertia ixx="0.0010405" ixy="-3.7268E-05" ixz="-3.9415E-05" iyy="0.0013244" iyz="-4.7638E-05" izz="0.00053219"/> 
    </inertial>  
    <visual> 
      <origin xyz="0 0 0" rpy="0 0 0"/>  
      <geometry> 
        <mesh filename="visual/glb/hand_base_link.glb"/> 
      </geometry>  
      <material name=""> 
        <color rgba="0.75294 0.75294 0.75294 1"/> 
      </material> 
    </visual>  
    <collision> 
      <origin xyz="0 0 0" rpy="0 0 0"/>  
      <geometry> 
        <mesh filename="collision/rough/hand_base_link.obj"/> 
      </geometry> 
    </collision> 
  </link>  
  <joint name="HAND_BASE" type="fixed"> 
    <origin xyz="0 0 0.002" rpy="0 0 0"/>  
    <parent link="connector_link"/>  
    <child link="hand_base_link"/> 
  </joint>  
  <link name="base_offset"> </link>  
  <joint name="BASE_OFFSET" type="fixed"> 
    <origin xyz="0 0.0298242 0" rpy="-0.0698132 0 0"/>  
    <parent link="hand_base_link"/>  
    <child link="base_offset"/>
  </joint>

  <link name="t_cmc_yaw_link"> 
    <inertial> 
      <origin xyz="0.0017239 0.0051432 -0.031065" rpy="0 0 0"/>  
      <mass value="0.005"/>  
      <inertia ixx="0.0010405" ixy="-3.7268E-05" ixz="-3.9415E-05" iyy="0.0013244" iyz="-4.7638E-05" izz="0.00053219"/> 
    </inertial>  
    <visual> 
      <origin xyz="0 0 0" rpy="0 0 0"/>  
      <geometry> 
        <mesh filename="visual/glb/t_cmc_yaw_link.glb"/> 
      </geometry>  
      <material name=""> 
        <color rgba="0.75294 0.75294 0.75294 1"/> 
      </material> 
    </visual>  
    <collision> 
      <origin xyz="0 0 0" rpy="0 0 0"/>  
      <geometry> 
        <mesh filename="collision/rough/t_cmc_yaw_link.obj"/> 
      </geometry> 
    </collision> 
  </link>  
  <link name="t_mcp_link"> 
    <inertial> 
      <origin xyz="0.0017239 0.0051432 -0.031065" rpy="0 0 0"/>  
      <mass value="0.04"/>  
      <inertia ixx="0.0010405" ixy="-3.7268E-05" ixz="-3.9415E-05" iyy="0.0013244" iyz="-4.7638E-05" izz="0.00053219"/> 
    </inertial>  
    <visual> 
      <origin xyz="0 0 0" rpy="0 0 0"/>  
      <geometry> 
        <mesh filename="visual/glb/t_mcp_link.glb"/> 
      </geometry>  
      <material name=""> 
        <color rgba="0.75294 0.75294 0.75294 1"/> 
      </material> 
    </visual>  
    <collision> 
      <origin xyz="0 0 0" rpy="0 0 0"/>  
      <geometry> 
        <mesh filename="collision/rough/t_mcp_link.obj"/> 
      </geometry> 
    </collision> 
  </link>  
  <link name="if_mcp_pitch_link"> 
    <inertial> 
      <origin xyz="0.0017239 0.0051432 -0.031065" rpy="0 0 0"/>  
      <mass value="0.008"/>  
      <inertia ixx="0.0010405" ixy="-3.7268E-05" ixz="-3.9415E-05" iyy="0.0013244" iyz="-4.7638E-05" izz="0.00053219"/> 
    </inertial>  
    <visual> 
      <origin xyz="0 0 0" rpy="0 0 0"/>  
      <geometry> 
        <mesh filename="visual/glb/if_mcp_pitch_link.glb"/> 
      </geometry>  
      <material name=""> 
        <color rgba="0.75294 0.75294 0.75294 1"/> 
      </material> 
    </visual>  
    <collision> 
      <origin xyz="0 0 0" rpy="0 0 0"/>  
      <geometry> 
        <mesh filename="collision/rough/if_mcp_pitch_link.obj"/> 
      </geometry> 
    </collision> 
  </link>  
  <link name="if_dip_link"> 
    <inertial> 
      <origin xyz="0.0017239 0.0051432 -0.031065" rpy="0 0 0"/>  
      <mass value="0.011"/>  
      <inertia ixx="0.0010405" ixy="-3.7268E-05" ixz="-3.9415E-05" iyy="0.0013244" iyz="-4.7638E-05" izz="0.00053219"/> 
    </inertial>  
    <visual> 
      <origin xyz="0 0 0" rpy="0 0 0"/>  
      <geometry> 
        <mesh filename="visual/glb/if_dip_link.glb"/> 
      </geometry>  
      <material name=""> 
        <color rgba="0.75294 0.75294 0.75294 1"/> 
      </material> 
    </visual>  
    <collision> 
      <origin xyz="0 0 0" rpy="0 0 0"/>  
      <geometry> 
        <mesh filename="collision/rough/if_dip_link.obj"/> 
      </geometry> 
    </collision> 
  </link>  
  <link name="mf_mcp_pitch_link"> 
    <inertial> 
      <origin xyz="0.0017239 0.0051432 -0.031065" rpy="0 0 0"/>  
      <mass value="0.011"/>  
      <inertia ixx="0.0010405" ixy="-3.7268E-05" ixz="-3.9415E-05" iyy="0.0013244" iyz="-4.7638E-05" izz="0.00053219"/> 
    </inertial>  
    <visual> 
      <origin xyz="0 0 0" rpy="0 0 0"/>  
      <geometry> 
        <mesh filename="visual/glb/mf_mcp_pitch_link.glb"/> 
      </geometry>  
      <material name=""> 
        <color rgba="0.75294 0.75294 0.75294 1"/> 
      </material> 
    </visual>  
    <collision> 
      <origin xyz="0 0 0" rpy="0 0 0"/>  
      <geometry> 
        <mesh filename="collision/rough/mf_mcp_pitch_link.obj"/> 
      </geometry> 
    </collision> 
  </link>  
  <link name="mf_dip_link"> 
    <inertial> 
      <origin xyz="0.0017239 0.0051432 -0.031065" rpy="0 0 0"/>  
      <mass value="0.011"/>  
      <inertia ixx="0.0010405" ixy="-3.7268E-05" ixz="-3.9415E-05" iyy="0.0013244" iyz="-4.7638E-05" izz="0.00053219"/> 
    </inertial>  
    <visual> 
      <origin xyz="0 0 0" rpy="0 0 0"/>  
      <geometry> 
        <mesh filename="visual/glb/mf_dip_link.glb"/> 
      </geometry>  
      <material name=""> 
        <color rgba="0.75294 0.75294 0.75294 1"/> 
      </material> 
    </visual>  
    <collision> 
      <origin xyz="0 0 0" rpy="0 0 0"/>  
      <geometry> 
        <mesh filename="collision/rough/mf_dip_link.obj"/> 
      </geometry> 
    </collision> 
  </link>  
  <link name="rf_mcp_pitch_link"> 
    <inertial> 
      <origin xyz="0.0017239 0.0051432 -0.031065" rpy="0 0 0"/>  
      <mass value="0.011"/>  
      <inertia ixx="0.0010405" ixy="-3.7268E-05" ixz="-3.9415E-05" iyy="0.0013244" iyz="-4.7638E-05" izz="0.00053219"/> 
    </inertial>  
    <visual> 
      <origin xyz="0 0 0" rpy="0 0 0"/>  
      <geometry> 
        <mesh filename="visual/glb/rf_mcp_pitch_link.glb"/> 
      </geometry>  
      <material name=""> 
        <color rgba="0.75294 0.75294 0.75294 1"/> 
      </material> 
    </visual>  
    <collision> 
      <origin xyz="0 0 0" rpy="0 0 0"/>  
      <geometry> 
        <mesh filename="collision/rough/rf_mcp_pitch_link.obj"/> 
      </geometry> 
    </collision> 
  </link>  
  <link name="rf_dip_link"> 
    <inertial> 
      <origin xyz="0.0017239 0.0051432 -0.031065" rpy="0 0 0"/>  
      <mass value="0.008"/>  
      <inertia ixx="0.0010405" ixy="-3.7268E-05" ixz="-3.9415E-05" iyy="0.0013244" iyz="-4.7638E-05" izz="0.00053219"/> 
    </inertial>  
    <visual> 
      <origin xyz="0 0 0" rpy="0 0 0"/>  
      <geometry> 
        <mesh filename="visual/glb/rf_dip_link.glb"/> 
      </geometry>  
      <material name=""> 
        <color rgba="0.75294 0.75294 0.75294 1"/> 
      </material> 
    </visual>  
    <collision> 
      <origin xyz="0 0 0" rpy="0 0 0"/>  
      <geometry> 
        <mesh filename="collision/rough/rf_dip_link.obj"/> 
      </geometry> 
    </collision> 
  </link>  
  <link name="lf_mcp_pitch_link"> 
    <inertial> 
      <origin xyz="0 0 0" rpy="0 0 0"/>  
      <mass value="0.008"/>  
      <inertia ixx="3.3526E-07" ixy="2.8461E-11" ixz="-2.3358E-12" iyy="1.0129E-07" iyz="2.1346E-08" izz="3.7096E-07"/> 
    </inertial>  
    <visual> 
      <origin xyz="0 0 0" rpy="0 0 0"/>  
      <geometry> 
        <mesh filename="visual/glb/lf_mcp_pitch_link.glb"/> 
      </geometry>  
      <material name=""> 
        <color rgba="1 1 1 1"/> 
      </material> 
    </visual>  
    <collision> 
      <origin xyz="0 0 0" rpy="0 0 0"/>  
      <geometry> 
        <mesh filename="collision/rough/lf_mcp_pitch_link.obj"/> 
      </geometry> 
    </collision> 
  </link>  
  <link name="lf_dip_link"> 
    <inertial> 
      <origin xyz="0.0017239 0.0051432 -0.031065" rpy="0 0 0"/>  
      <mass value="0.008"/>  
      <inertia ixx="0.0010405" ixy="-3.7268E-05" ixz="-3.9415E-05" iyy="0.0013244" iyz="-4.7638E-05" izz="0.00053219"/> 
    </inertial>  
    <visual> 
      <origin xyz="0 0 0" rpy="0 0 0"/>  
      <geometry> 
        <mesh filename="visual/glb/lf_dip_link.glb"/> 
      </geometry>  
      <material name=""> 
        <color rgba="0.75294 0.75294 0.75294 1"/> 
      </material> 
    </visual>  
    <collision> 
      <origin xyz="0 0 0" rpy="0 0 0"/>  
      <geometry> 
        <mesh filename="collision/rough/lf_dip_link.obj"/> 
      </geometry> 
    </collision> 
  </link>  



  <joint name="T_CMC_YAW" type="revolute"> 
    <origin xyz="-0.0245 0.022632 0.023263" rpy="0.14578 -1.0699 -0.12808"/>  
    <parent link="base_offset"/>  
    <child link="t_cmc_yaw_link"/>  
    <axis xyz="0 1 0"/>  
    <limit lower="0" upper="1.5708" effort="0" velocity="0"/>  
    <dynamics damping="0" friction="0"/> 
  </joint>  
  <joint name="T_MCP" type="revolute"> 
    <origin xyz="0 0 0.013647" rpy="0.87266 -0.49642 0"/>  
    <parent link="t_cmc_yaw_link"/>  
    <child link="t_mcp_link"/>  
    <axis xyz="-1 0 0"/>  
    <limit lower="0" upper="0.8727" effort="0" velocity="0"/>  
    <dynamics damping="0" friction="0"/> 
  </joint>  
  <joint name="IF_MCP_PITCH" type="revolute"> 
    <origin xyz="-0.029003 0.088291 0.0022155" rpy="-0.029415 0.05236 0.034907"/>  
    <parent link="base_offset"/>  
    <child link="if_mcp_pitch_link"/>  
    <axis xyz="1 0 0"/>  
    <limit lower="0" upper="1.309" effort="0" velocity="0"/>  
    <dynamics damping="0" friction="0"/> 
  </joint>  
  <joint name="IF_DIP" type="revolute"> 
    <origin xyz="0 0.035 0" rpy="0.19353 0 0"/>  
    <parent link="if_mcp_pitch_link"/>  
    <child link="if_dip_link"/>  
    <axis xyz="1 0 0"/>  
    <limit lower="0" upper="2.0944" effort="0" velocity="0"/> 
    <mimic joint="IF_MCP_PITCH" multiplier="1.2" offset="0.19373154697137057"/>
  </joint>  
  <joint name="MF_MCP_PITCH" type="revolute"> 
    <origin xyz="-0.008 0.092284 -0.0017707" rpy="0 0 0"/>  
    <parent link="base_offset"/>  
    <child link="mf_mcp_pitch_link"/>  
    <axis xyz="1 0 0"/>  
    <limit lower="0" upper="1.309" effort="0" velocity="0"/>  
    <dynamics damping="0" friction="0"/> 
  </joint>  
  <joint name="MF_DIP" type="revolute"> 
    <origin xyz="0 0.042 0" rpy="0.18357 0 0"/>  
    <parent link="mf_mcp_pitch_link"/>  
    <child link="mf_dip_link"/>  
    <axis xyz="1 0 0"/>  
    <limit lower="0" upper="2.0944" effort="0" velocity="0"/> 
    <mimic joint="MF_MCP_PITCH" multiplier="1.2" offset="0.1832595714594046"/>
  </joint>  
  <joint name="RF_MCP_PITCH" type="revolute"> 
    <origin xyz="0.013103 0.090291 -0.0017845" rpy="-0.0092374 -0.05236 -0.034907"/>  
    <parent link="base_offset"/>  
    <child link="rf_mcp_pitch_link"/>  
    <axis xyz="1 0 0"/>  
    <limit lower="0" upper="1.309" effort="0" velocity="0"/>  
    <dynamics damping="0" friction="0"/> 
  </joint>  
  <joint name="RF_DIP" type="revolute"> 
    <origin xyz="0 0.042 0" rpy="0.16583 0 0"/>  
    <parent link="rf_mcp_pitch_link"/>  
    <child link="rf_dip_link"/>  
    <axis xyz="1 0 0"/>  
    <limit lower="0" upper="2.0944" effort="0" velocity="0"/> 
    <mimic joint="RF_MCP_PITCH" multiplier="1.2" offset="0.16580627893946132"/>
  </joint>  
  <joint name="LF_MCP_PITCH" type="revolute"> 
    <origin xyz="0.033731 0.083777 0.0022155" rpy="-0.024909 -0.05236 -0.069813"/>  
    <parent link="base_offset"/>  
    <child link="lf_mcp_pitch_link"/>  
    <axis xyz="1 0 0"/>  
    <limit lower="0" upper="1.309" effort="0" velocity="0"/>  
    <dynamics damping="0" friction="0"/> 
  </joint>  
  <joint name="LF_DIP" type="revolute"> 
    <origin xyz="0 0.035 0" rpy="0.20294 0 0"/>  
    <parent link="lf_mcp_pitch_link"/>  
    <child link="lf_dip_link"/>  
    <axis xyz="1 0 0"/>  
    <limit lower="0" upper="2.0944" effort="0" velocity="0"/> 
    <mimic joint="LF_MCP_PITCH" multiplier="1.2" offset="0.20245819323134223"/>
  </joint> 
</robot>
